Workbook

Sheet Seguimiento
B3: Estado semanal
B6: 1. Estado captación integradores
B8: Estado | C8: Empresa | D8: % sobre total | E8: Observaciones
B9: 0. Pendiente contactar | C9: =+INDEX('Summary Captación INT >>'!$C$5:$E$19,MATCH($B9,'Summary Captación INT >>'!$B$5:$B$19,0),MATCH(C$8,'Summary Captación INT >>'!$C$4:$E$4,0)) -> 437 | D9: =+INDEX('Summary Captación INT >>'!$C$5:$E$19,MATCH($B9,'Summary Captación INT >>'!$B$5:$B$19,0),MATCH(D$8,'Summary Captación INT >>'!$C$4:$E$4,0)) -> 0.22261844
B10: 0. Contacto fallido (sin descuelgue) | C10: =+INDEX('Summary Captación INT >>'!$C$5:$E$19,MATCH($B10,'Summary Captación INT >>'!$B$5:$B$19,0),MATCH(C$8,'Summary Captación INT >>'!$C$4:$E$4,0)) -> #N/A | D10: =+INDEX('Summary Captación INT >>'!$C$5:$E$19,MATCH($B10,'Summary Captación INT >>'!$B$5:$B$19,0),MATCH(D$8,'Summary Captación INT >>'!$C$4:$E$4,0)) -> #N/A
B11: 1. Contactado con interés | C11: =+INDEX('Summary Captación INT >>'!$C$5:$E$19,MATCH($B11,'Summary Captación INT >>'!$B$5:$B$19,0),MATCH(C$8,'Summary Captación INT >>'!$C$4:$E$4,0)) -> #N/A | D11: =+INDEX('Summary Captación INT >>'!$C$5:$E$19,MATCH($B11,'Summary Captación INT >>'!$B$5:$B$19,0),MATCH(D$8,'Summary Captación INT >>'!$C$4:$E$4,0)) -> #N/A
B12: 2. Rechazados / muertos (KO) | C12: =+INDEX('Summary Captación INT >>'!$C$5:$E$19,MATCH($B12,'Summary Captación INT >>'!$B$5:$B$19,0),MATCH(C$8,'Summary Captación INT >>'!$C$4:$E$4,0)) -> #N/A | D12: =+INDEX('Summary Captación INT >>'!$C$5:$E$19,MATCH($B12,'Summary Captación INT >>'!$B$5:$B$19,0),MATCH(D$8,'Summary Captación INT >>'!$C$4:$E$4,0)) -> #N/A | E12: =+INDEX('Summary Captación INT >>'!$C$5:$E$19,MATCH($B12,'Summary Captación INT >>'!$B$5:$B$19,0),MATCH(E$8,'Summary Captación INT >>'!$C$4:$E$4,0)) -> #N/A
B13: 3. Sesión agendada | C13: =+INDEX('Summary Captación INT >>'!$C$5:$E$19,MATCH($B13,'Summary Captación INT >>'!$B$5:$B$19,0),MATCH(C$8,'Summary Captación INT >>'!$C$4:$E$4,0)) -> #N/A | D13: =+INDEX('Summary Captación INT >>'!$C$5:$E$19,MATCH($B13,'Summary Captación INT >>'!$B$5:$B$19,0),MATCH(D$8,'Summary Captación INT >>'!$C$4:$E$4,0)) -> #N/A | E13: =+INDEX('Summary Captación INT >>'!$C$5:$E$19,MATCH($B13,'Summary Captación INT >>'!$B$5:$B$19,0),MATCH(E$8,'Summary Captación INT >>'!$C$4:$E$4,0)) -> #N/A
B14: 4. Interés en evaluación | C14: =+INDEX('Summary Captación INT >>'!$C$5:$E$19,MATCH($B14,'Summary Captación INT >>'!$B$5:$B$19,0),MATCH(C$8,'Summary Captación INT >>'!$C$4:$E$4,0)) -> #N/A | D14: =+INDEX('Summary Captación INT >>'!$C$5:$E$19,MATCH($B14,'Summary Captación INT >>'!$B$5:$B$19,0),MATCH(D$8,'Summary Captación INT >>'!$C$4:$E$4,0)) -> #N/A | E14: =+INDEX('Summary Captación INT >>'!$C$5:$E$19,MATCH($B14,'Summary Captación INT >>'!$B$5:$B$19,0),MATCH(E$8,'Summary Captación INT >>'!$C$4:$E$4,0)) -> #N/A
B15: 4. Interés confirmado | C15: =+INDEX('Summary Captación INT >>'!$C$5:$E$19,MATCH($B15,'Summary Captación INT >>'!$B$5:$B$19,0),MATCH(C$8,'Summary Captación INT >>'!$C$4:$E$4,0)) -> #N/A | D15: =+INDEX('Summary Captación INT >>'!$C$5:$E$19,MATCH($B15,'Summary Captación INT >>'!$B$5:$B$19,0),MATCH(D$8,'Summary Captación INT >>'!$C$4:$E$4,0)) -> #N/A | E15: =+INDEX('Summary Captación INT >>'!$C$5:$E$19,MATCH($B15,'Summary Captación INT >>'!$B$5:$B$19,0),MATCH(E$8,'Summary Captación INT >>'!$C$4:$E$4,0)) -> #N/A
B16: 5. Documentación de firma en proceso | C16: =+INDEX('Summary Captación INT >>'!$C$5:$E$19,MATCH($B16,'Summary Captación INT >>'!$B$5:$B$19,0),MATCH(C$8,'Summary Captación INT >>'!$C$4:$E$4,0)) -> #N/A | D16: =+INDEX('Summary Captación INT >>'!$C$5:$E$19,MATCH($B16,'Summary Captación INT >>'!$B$5:$B$19,0),MATCH(D$8,'Summary Captación INT >>'!$C$4:$E$4,0)) -> #N/A | E16: =+INDEX('Summary Captación INT >>'!$C$5:$E$19,MATCH($B16,'Summary Captación INT >>'!$B$5:$B$19,0),MATCH(E$8,'Summary Captación INT >>'!$C$4:$E$4,0)) -> #N/A
B17: 6. Firmado | C17: =+INDEX('Summary Captación INT >>'!$C$5:$E$19,MATCH($B17,'Summary Captación INT >>'!$B$5:$B$19,0),MATCH(C$8,'Summary Captación INT >>'!$C$4:$E$4,0)) -> #N/A | D17: =+INDEX('Summary Captación INT >>'!$C$5:$E$19,MATCH($B17,'Summary Captación INT >>'!$B$5:$B$19,0),MATCH(D$8,'Summary Captación INT >>'!$C$4:$E$4,0)) -> #N/A | E17: =+INDEX('Summary Captación INT >>'!$C$5:$E$19,MATCH($B17,'Summary Captación INT >>'!$B$5:$B$19,0),MATCH(E$8,'Summary Captación INT >>'!$C$4:$E$4,0)) -> #N/A
B18: 97. Churn | C18: =+INDEX('Summary Captación INT >>'!$C$5:$E$20,MATCH($B18,'Summary Captación INT >>'!$B$5:$B$20,0),MATCH(C$8,'Summary Captación INT >>'!$C$4:$E$4,0)) -> #N/A | D18: =+INDEX('Summary Captación INT >>'!$C$5:$E$20,MATCH($B18,'Summary Captación INT >>'!$B$5:$B$20,0),MATCH(D$8,'Summary Captación INT >>'!$C$4:$E$4,0)) -> #N/A | E18: =+INDEX('Summary Captación INT >>'!$C$5:$E$19,MATCH($B18,'Summary Captación INT >>'!$B$5:$B$19,0),MATCH(E$8,'Summary Captación INT >>'!$C$4:$E$4,0)) -> #N/A
B19: 98. Descartado del proceso | C19: =+INDEX('Summary Captación INT >>'!$C$5:$E$20,MATCH($B19,'Summary Captación INT >>'!$B$5:$B$20,0),MATCH(C$8,'Summary Captación INT >>'!$C$4:$E$4,0)) -> #N/A | D19: =+INDEX('Summary Captación INT >>'!$C$5:$E$20,MATCH($B19,'Summary Captación INT >>'!$B$5:$B$20,0),MATCH(D$8,'Summary Captación INT >>'!$C$4:$E$4,0)) -> #N/A | E19: =+INDEX('Summary Captación INT >>'!$C$5:$E$19,MATCH($B19,'Summary Captación INT >>'!$B$5:$B$19,0),MATCH(E$8,'Summary Captación INT >>'!$C$4:$E$4,0)) -> #N/A
B20: Total | C20: =+INDEX('Summary Captación INT >>'!$C$5:$E$19,MATCH($B20,'Summary Captación INT >>'!$B$5:$B$19,0),MATCH(C$8,'Summary Captación INT >>'!$C$4:$E$4,0)) -> #N/A
B21: Total captados | C21: =SUM(C15:C17) -> #N/A
B23: Highlights
B24: Nuevo integrador con interés en evaluación (INFORNET)
B28: Aspectos a movilizar | C28: Fecha esperada | D28: Nueva fecha | E28: Criticidad | F28: Responsable
B29: Hacer seguimiento al grupo de 2 empezando el proceso de firma | C29: Continuo | F29: Accenture
B33: 2. Estado contratos
B35: Integrador | C35: Envío documentación | D35: Revisión legal | E35: Firma contrato | F35: Creación SFID | G35: Comentarios
B36: Cover Net | C36: Finalizado | D36: Finalizado | E36: Finalizado | F36: Finalizado
B37: Maxen | C37: Finalizado | D37: Finalizado | E37: Finalizado | F37: Finalizado
B38: Deiteco | C38: Finalizado | D38: Finalizado | E38: En curso | F38: Pendiente
B39: Duo IT | C39: En curso | D39: Pendiente | E39: Pendiente | F39: Pendiente
B40: Land M | C40: Pendiente | D40: Pendiente | E40: Pendiente | F40: Pendiente
B41: Dataqu | C41: Pendiente | D41: Pendiente | E41: Pendiente | F41: Pendiente
B42: Octivitas | C42: Pendiente | D42: Pendiente | E42: Pendiente | F42: Pendiente | G42: Pendiente envío contrato + anexo renovación (pendiente finalización legal)
B43: Paperlabs | G43: Retraso en participación
B44: Ox-one | C44: Pendiente | D44: Pendiente | E44: Pendiente | F44: Pendiente
B45: Microsip | C45: Pendiente | D45: Pendiente | E45: Pendiente | F45: Pendiente
B46: SICTEMAS | C46: Pendiente | D46: Pendiente | E46: Pendiente | F46: Pendiente
B47: Fedesoft | C47: Pendiente | D47: Pendiente | E47: Pendiente | F47: Pendiente
B51: Highlights
B52: + 3 sesiones presenciales agendadas: Ox-one (10.12); Fedesoft (13.01); SICTEMAS (09.01)
B55: Aspectos a movilizar | C55: Fecha esperada | D55: Nueva fecha | E55: Criticidad | F55: Responsable
B56: Nuevo modelo contrato Colaborador de Leads | C56: 45996 | D56: 46000 | E56: Alta | F56: Legal
B57: Anexo económico Colaborador de Leads | C57: 45996 | D57: 46000 | E57: Alta | F57: ACN, Finanzas
B58: Envío del contrato de Leadgen + anexo renovación a Octivitas | C58: 45981 | D58: 46000 | E58: Alta | F58: Legal, Eloy
...

Sheet Summary Captación INT >>
B2: Leads priorizados
B4: Estado | C4: Empresa | D4: % sobre total | E4: Observaciones
B5: 0. Pendiente contactar | C5: =+IFERROR(_xlfn.XLOOKUP(B5,$B$24:$B$38,$C$24:$C$38),"0") -> 437 | D5: =+C5/$C$20 -> 0.22261844
B6: 1.0. Contacto fallido (sin descuelgue) | C6: =+IFERROR(_xlfn.XLOOKUP(B6,$B$24:$B$38,$C$24:$C$38),"0") -> 190 | D6: =+C6/$C$20 -> 0.096790627
B7: 1.1 Contactado: propuesta "rechazada" | C7: =+IFERROR(_xlfn.XLOOKUP(B7,$B$24:$B$38,$C$24:$C$38),"0") -> 206 | D7: =+C7/$C$20 -> 0.10494142
B8: 1.2 Contactado: propuesta "en valoración" | C8: =+IFERROR(_xlfn.XLOOKUP(B8,$B$24:$B$38,$C$24:$C$38),"0") -> 407 | D8: =+C8/$C$20 -> 0.20733571
B9: 1.3 Contactado "muerto" | C9: =+IFERROR(_xlfn.XLOOKUP(B9,$B$24:$B$38,$C$24:$C$38),"0") -> 154 | D9: =+C9/$C$20 -> 0.07845135
B10: 2.1 Acepta Sesión 1:1 - pendiente agendar | C10: =+IFERROR(_xlfn.XLOOKUP(B10,$B$24:$B$38,$C$24:$C$38),"0") -> 1 | D10: =+C10/$C$20 -> 0.00050942435
B11: 2.2 Acepta Sesión 1:1 - agendada | C11: =+IFERROR(_xlfn.XLOOKUP(B11,$B$24:$B$38,$C$24:$C$38),"0") -> 3 | D11: =+C11/$C$20 -> 0.0015282731
B12: 2.3 Rechaza tras Sesión 1:1 | C12: =+IFERROR(_xlfn.XLOOKUP(B12,$B$24:$B$38,$C$24:$C$38),"0") -> 19 | D12: =+C12/$C$20 -> 0.0096790627
B13: 3.1 Interés confirmado: pendiente agendar KO | C13: =+IFERROR(_xlfn.XLOOKUP(B13,$B$24:$B$38,$C$24:$C$38),"0") -> 8 | D13: =+C13/$C$20 -> 0.0040753948
B14: 3.2 Interés confirmado: agendado KO | C14: =+IFERROR(_xlfn.XLOOKUP(B14,$B$24:$B$38,$C$24:$C$38),"0") -> 4 | D14: =+C14/$C$20 -> 0.0020376974
B15: 3.3 Interés confirmado: on hold | C15: =+IFERROR(_xlfn.XLOOKUP(B15,$B$24:$B$38,$C$24:$C$38),"0") -> 4 | D15: =+C15/$C$20 -> 0.0020376974
B16: 4.1 Activado: en proceso de firma | C16: =+IFERROR(_xlfn.XLOOKUP(B16,$B$24:$B$38,$C$24:$C$38),"0") -> 17 | D16: =+C16/$C$20 -> 0.008660214
... B19: 99. Descartado | C19: =+IFERROR(_xlfn.XLOOKUP(B19,$B$24:$B$38,$C$24:$C$38),"0") -> 499 | D19: =+C19/$C$20 -> 0.25420275
B20: Grand Total | C20: =+SUM(C5:C19) -> 1963
B23: Row Labels | C23: Count of Empresa
B24: 0. Pendiente contactar | C24: 437
B25: 1.0. Contacto fallido (sin descuelgue) | C25: 190
B26: 1.1 Contactado: propuesta "rechazada" | C26: 206
B27: 1.2 Contactado: propuesta "en valoración" | C27: 407
B28: 1.3 Contactado "muerto" | C28: 154
B29: 2.1 Acepta Sesión 1:1 - pendiente agendar | C29: 1
B30: 2.2 Acepta Sesión 1:1 - agendada | C30: 3
B31: 2.3 Rechaza tras Sesión 1:1 | C31: 19
B32: 3.1 Interés confirmado: pendiente agendar KO | C32: 8
B33: 3.2 Interés confirmado: agendado KO | C33: 4
B34: 3.3 Interés confirmado: on hold | C34: 4
B35: 4.1 Activado: en proceso de firma | C35: 17
... B39: Grand Total | C39: 1963
B49: 0. Pendiente contactar
B50: 1.0. Contacto fallido (sin descuelgue)
B51: 1.1 Contactado: propuesta "rechazada"
B52: 1.2 Contactado: propuesta "en valoración"
B53: 1.3 Contactado "muerto"
B54: 2.1 Acepta Sesión 1:1 - pendiente agendar
B55: 2.2 Acepta Sesión 1:1 - agendada
B56: 2.3 Rechaza tras Sesión 1:1
B57: 3.1 Interés confirmado: pendiente agendar KO
B58: 3.2 Interés confirmado: agendado KO
...

Sheet Resumen Estados
B2: Hito | C2: Nombre | D2: Definición | E2: #integradores | G2: % | L2: 0. Pendiente contactar | M2: 0. Pendiente contactar
C3: Total Fishing Pool Integradores | D3: Total de integradores en el fishing pool | E3: =+COUNTA('BBDD Completa'!E2:E5125) -> 5124 | F3: Suma todos | L3: 0. Contacto fallido (sin descuelgue) | M3: 1.0 Contacto fallido (sin descuelgue)
C4: Fishing Pool Priorizada Fase Lanzamiento | D4: Total de integradores priorizados para esta primera ronda de contactos | E4: =+COUNTA('Leads Priorizados INT'!B4:B1436) -> 1433 | F4: Suma todos en esta BBDD | L4: 1. Contactado | M4: 1.2 Contactado: propuesta "en valoración"
C5: Descartados | D5: Descartados por (1) número no disponible, (2) cierre, (3) no encaja en programa | E5: =+GETPIVOTDATA("Empresa",'Summary Captación INT >>'!$B$23,"Estado","99. Descartado") -> 499 | F5: 99. Descartado | L5: 1. Contactado "con interés" | M5: 1.2 Contactado: propuesta "en valoración"
C6: Pendientes de contactar | E6: =+GETPIVOTDATA("Empresa",'Summary Captación INT >>'!$B$23,"Estado","0. Pendiente contactar") -> 437 | F6: 0. Pendiente contactar | L6: 1. Contactado "muerto" | M6: 1.3 Contactado: "muerto"
C7: Contacto fallido | D7: Se ha realizado un primer contacto telefónico sin éxito: (1) sin descuelgue, (2) volver a llamar por contacto erróneo | E7: =+GETPIVOTDATA("Empresa",'Summary Captación INT >>'!$B$23,"Estado","1.0. Contacto fallido (sin descuelgue)") -> 190 | F7: 0. Contacto fallido (sin descuelgue) | L7: 2. Rechazado | M7: 1.1 Contactado: propuesta "rechazada"
B8: Hito 1: contacto establecido | C8: Primer contacto (telefónico) | D8: Hemos conseguido establecer contacto con la persona adecuada de la organización del integrador | E8: =+GETPIVOTDATA("Empresa",'Summary Captación INT >>'!$B$23)-GETPIVOTDATA("Empresa",'Summary Captación INT >>'!$B$23,"Estado","0. Pendiente contactar")-GETPIVOTDATA("Empresa",'Summary Captación INT >>'!$B$23,"Estado","1.0. Contacto fallido (sin descuelgue)")-GETPIVOTDATA("Empresa",'Summary Captación INT >>'!$B$23,"Estado","99. Descartado") -> 837 | F8: Todos - 99 - 98 - 0 | G8: =+E8/E3 -> 0.16334895 | H8: Sobre el total | L8: 3.0 Quiere sesión 1:1 - pendiente agendar | M8: 2.1 Acepta Sesión 1:1 - pendiente agendar
C9: Rechazado / No contesta | D9: Propuesta rechazada por (1) falta de interés en propuesta, (2) sin encaje con modelo de negocio; o por no haber recibido respuesta después de 3 intentos de contacto | E9: =+GETPIVOTDATA("Empresa",'Summary Captación INT >>'!$B$23,"Estado","1.1 Contactado: propuesta ""rechazada""")+GETPIVOTDATA("Empresa",'Summary Captación INT >>'!$B$23,"Estado","1.3 Contactado ""muerto""") -> 360 | F9: 1. Contactado "muerto" & 2. Rechazado (KO) | L9: 3. Sesión agendada | M9: 2.2 Acepta Sesión 1:1 - agendada
C10: Requiere re-contacto | D10: Interés mostrado en propuesta, pendiente recontactar para mantener interés y cerrar sesión 1:1 | E10: =+GETPIVOTDATA("Empresa",'Summary Captación INT >>'!$B$23,"Estado","1.2 Contactado: propuesta ""en valoración""") -> 407 | F10: 1. Contactado & 1. Contactado "con interés" | L10: 3.1 Rechazado tras sesión online 1:1 | M10: 2.3 Rechaza tras Sesión 1:1 | N10: No continúa en proceso de onboarding tras la sesión informativa del programa
B11: Hito 2: Lead con Interés | C11: Acepta Sesión Informativa 1:1 (online) | E11: =+GETPIVOTDATA("Empresa",'Summary Captación INT >>'!$B$23)-GETPIVOTDATA("Empresa",'Summary Captación INT >>'!$B$23,"Estado","0. Pendiente contactar")-GETPIVOTDATA("Empresa",'Summary Captación INT >>'!$B$23,"Estado","1.0. Contacto fallido (sin descuelgue)")-GETPIVOTDATA("Empresa",'Summary Captación INT >>'!$B$23,"Estado","1.1 Contactado: propuesta ""rechazada""")-GETPIVOTDATA("Empresa",'Summary Captación INT >>'!$B$23,"Estado","1.2 Contactado: propuesta ""en valoración""")-GETPIVOTDATA("Empresa",'Summary Captación INT >>'!$B$23,"Estado","1.3 Contactado ""muerto""")-GETPIVOTDATA("Empresa",'Summary Captación INT >>'!$B$23,"Estado","99. Descartado") -> 70 | F11: Todos - los anteriores | L11: 4.1 Interés confirmado: pendiente agendar | M11: 3.1 Interés confirmado: pendiente agendar KO
C12: Pendiente sesión: sin agendar | D12: Acepta sesión informativa 1:1 pero está pendiente de agendar | E12: =+GETPIVOTDATA("Empresa",'Summary Captación INT >>'!$B$23,"Estado","2.1 Acepta Sesión 1:1 - pendiente agendar") -> 1 | F12: 3.0 Pendiente agendar | L12: 4.2 Interés confirmado: agendada | M12: 3.2 Interés confirmado: agendado KO
C13: Pendiente sesión: agendada | D13: Acepta sesión informativa 1:1 y está agendada | E13: =+GETPIVOTDATA("Empresa",'Summary Captación INT >>'!$B$23,"Estado","2.2 Acepta Sesión 1:1 - agendada") -> 3 | F13: 3. Sesión agendada | L13: 5. En proceso de firma | M13: 4.1 Activado: en proceso de firma
C14: Rechazado post sesión | D14: Rechaza propuesta por falta de interés o no encaje con modelo | E14: =+GETPIVOTDATA("Empresa",'Summary Captación INT >>'!$B$23,"Estado","2.3 Rechaza tras Sesión 1:1") -> 19 | F14: 3.1 Rechazado tras sesión online | L14: 6. Firmado | M14: 4.2 Activado: Firmado
B15: Hito 3: Integrador Captado | C15: Acepta sesión Kick Off (presencial) | D15: Acepta reunión presencial | E15: =+GETPIVOTDATA("Empresa",'Summary Captación INT >>'!$B$23,"Estado","3.1 Interés confirmado: pendiente agendar KO")+IFERROR(GETPIVOTDATA("Empresa",'Summary Captación INT >>'!$B$23,"Estado","3.2 Interés confirmado: agendado KO"),0)+GETPIVOTDATA("Empresa",'Summary Captación INT >>'!$B$23,"Estado","4.1 Activado: en proceso de firma")+GETPIVOTDATA("Empresa",'Summary Captación INT >>'!$B$23,"Estado","4.2 Activado: Firmado")+GETPIVOTDATA("Empresa",'Summary Captación INT >>'!$B$23,"Estado","98. Churn")+GETPIVOTDATA("Empresa",'Summary Captación INT >>'!$B$23,"Estado","3.3 Interés confirmado: on hold") -> 47 | F15: 3.1+3.2+98+4.1+4.2 | G15: =+E15/$E$8 -> 0.056152927 | H15: Sobre los contactados | L15: 97. Churn | M15: 4.3 Churn | N15: Hace churn después de sesión de kick-off
C16: Pendiente sesión: sin agendar | D16: Acepta reunión presencial, pendiente de agendar | E16: =+GETPIVOTDATA("Empresa",'Summary Captación INT >>'!$B$23,"Estado","3.1 Interés confirmado: pendiente agendar KO") -> 8 | F16: 3.1 | L16: 98. Descartado del proceso | M16: 99. Descartado | N16: Lo descartamos del proceso por (1) cierre, (2) objeto social no aplicable o (3) xxxx
C17: Pendiente sesión: agendada | D17: Acepta reunión presencial, agendada | E17: =+IFERROR(GETPIVOTDATA("Empresa",'Summary Captación INT >>'!$B$23,"Estado","3.2 Interés confirmado: agendado KO"),0) -> 4 | F17: 3.2 | L17: 99. Descartado por objeto social
C18: Pendiente sesión: sin contacto | D18: Acepta reunión presencial/online, pero no se consigue continuar contacto | E18: =+IFERROR(GETPIVOTDATA("Empresa",'Summary Captación INT >>'!$B$23,"Estado","3.3 Interés confirmado: on hold"),0) -> 4
C19: Churn post kick off | D19: Rechazo de propuesta después de la reunión presencial | E19: =+GETPIVOTDATA("Empresa",'Summary Captación INT >>'!$B$23,"Estado","98. Churn") -> 8 | F19: 98
B20: Hito 4: Integrador Activado | C20: ACTIVADO | E20: =+GETPIVOTDATA("Empresa",'Summary Captación INT >>'!$B$23,"Estado","4.1 Activado: en proceso de firma")+GETPIVOTDATA("Empresa",'Summary Captación INT >>'!$B$23,"Estado","4.2 Activado: Firmado") -> 23 | F20: SUMA DE 5 Y 6 | G20: =+E20/$E$8 -> 0.027479092 | H20: Sobre los contactados
C21: En proceso de firma | E21: =+GETPIVOTDATA("Empresa",'Summary Captación INT >>'!$B$23,"Estado","4.1 Activado: en proceso de firma") -> 17
B22: Hito 5: Firma de contrato | C22: Firmado | E22: =+GETPIVOTDATA("Empresa",'Summary Captación INT >>'!$B$23,"Estado","4.2 Activado: Firmado") -> 6
B27: Definición por estado
B29: Estado | C29: Definición
B30: 0. Pendiente contactar | C30: Empresa sin contactar
B31: 1.0 Contacto fallido (sin descuelgue) | C31: Contacto sin descuelgue. Volver a contactar
B32: 1.2 Contactado: propuesta "rechazado" | C32: Primer contacto establecido, integrador no interesado en la propuesta (e.g. no encaje con su modelo de negocio, no interesado en colaborar en este momento, etc.)
B33: 1.2 Contactado: propuesta "en valoración" | C33: Primer contacto establecido, integrador interesado en la propuesta. Se envía correo informativo y se agenda sesión 1:1 o se solicita disponibilidad para agendar dicha sesión
B34: 1.3 Contactado: "muerto" | C34: Contacto perdido. Previo estado 1.2) pero no ha vuelto a contestar en +3 semanas, incluyendo recontacto
B35: 2.1 Acepta Sesión 1:1 - pendiente agendar | C35: Pendiente agendar sesión online 1:1, sujeta a disponibilidad de la empresa
B36: 2.2 Acepta Sesión 1:1 - agendada | C36: Sesión online 1:1 aceptada y agendada
B37: 2.3 Rechaza tras Sesión 1:1 | C37: No continúa en proceso de onboarding tras la sesión informativa del programa
B38: 3.1 Interés confirmado: pendiente agendar KO | C38: Después de la sesión online, sigue con interés en el modelo y en mantener una sesión presencial de KickOff. Pendiente agendar el KickOff
B39: 3.2 Interés confirmado: agendado KO | C39: Sesión KickOff agendada (presencial u online)
B40: 4.1 Activado: en proceso de firma | C40: Integrador activado, en proceso de firma de contrato
... B43: 99. Descartado | C43: Lo descartamos del proceso por (1) cierre, (2) objeto social no aplicable o (3) compañía no activa, (4) etc.

Sheet Leads
B2: Funnel leads
E3: Correo
C4: Leads potenciales | D4: Leads pendientes de identificar | E4: Leads activados | F4: Ventas realizadas | G4: Leads en curso | H4: Pendiente info para realizar oferta | I4: KO
C5: =+COUNTA(B11:B217) -> 53 | D5: =+C5-E5 -> 0 | E5: =+COUNTA(G11:G217) -> 53 | F5: =+COUNTIF($I$11:$I$1048576,"Venta realizada") -> 6 | G5: =+COUNTIF($I$11:$I$1048576,"En curso") -> 11 | H5: =+COUNTIFS($G$11:$G$1048576,"<>",$I$11:$I$1048576,"Pendiente") -> 28 | I5: =+COUNTIF($I$11:$I$1048576,"ko") -> 8 | J5: =+SUM(F5:I5)=E5 -> TRUE
D6: =+D5/$C$5 -> 0 | E6: =+E5/$C$5 -> 1 | F6: =+F5/$E$5 -> 0.11320755 | G6: =+G5/$E$5 -> 0.20754717 | H6: =+H5/E5 -> 0.52830189 | I6: =+I5/E5 -> 0.1509434
H7: 9
H8: =+H7/G5 -> 0.81818182
B10: Id | C10: Nombre del lead | D10: CIF lead | E10: Integrador | F10: Modelo | G10: Fecha de generación lead | H10: Comercial asignado | I10: Estado de oferta | J10: Fecha de firma oferta | K10: Segmento | L10: Siguiente paso - Equipo gestión | M10: Fecha | N10: Siguiente paso comercial | O10: Fecha | P10: Venta mes | Q10: Tipos de productos | R10: Variable ACN
B11: 1 | C11: Autocars Barrera | D11: B60416302 | E11: MAXEN TECHNOLOGIES SL | F11: Tier 2 | G11: 45966 | H11: Didac | I11: Venta realizada | J11: 46011 | L11: N/A | M11: N/A | N11: N/A | O11: N/A | P11: 361 | Q11: 9 líneas móviles, 3 líneas FBB, Con Centralita | S11: dato no disponible - pedir a CB
B12: 2 | C12: Lead 10 | E12: MAXEN TECHNOLOGIES SL | F12: Tier 2 | G12: 45966 | H12: Didac | I12: Pendiente | L12: Pendiente lead | N12: Pendiente lead
B13: 3 | C13: Lead 11 | E13: MAXEN TECHNOLOGIES SL | F13: Tier 2 | G13: 45966 | H13: Didac | I13: Pendiente | L13: Pendiente lead | N13: Pendiente lead
B14: 4 | C14: Lead 12 | E14: MAXEN TECHNOLOGIES SL | F14: Tier 2 | G14: 45966 | H14: Didac | I14: Pendiente | L14: Pendiente lead | N14: Pendiente lead
B15: 5 | C15: Lead 13 | E15: MAXEN TECHNOLOGIES SL | F15: Tier 2 | G15: 45966 | H15: Didac | I15: Pendiente | L15: Pendiente lead | N15: Pendiente lead
B16: 6 | C16: Lead 14 | E16: MAXEN TECHNOLOGIES SL | F16: Tier 2 | G16: 45966 | H16: Didac | I16: Pendiente | L16: Pendiente lead | N16: Pendiente lead
B17: 7 | C17: Lead 15 | E17: MAXEN TECHNOLOGIES SL | F17: Tier 2 | G17: 45966 | H17: Didac | I17: Pendiente | L17: Pendiente lead | N17: Pendiente lead
B18: 8 | C18: Lead 16 | E18: MAXEN TECHNOLOGIES SL | F18: Tier 2 | G18: 45966 | H18: Didac | I18: Pendiente | L18: Pendiente lead | N18: Pendiente lead
B19: 9 | C19: Lead 17 | E19: MAXEN TECHNOLOGIES SL | F19: Tier 2 | G19: 45966 | H19: Didac | I19: Pendiente | L19: Pendiente lead | N19: Pendiente lead
B20: 10 | C20: Lead 18 | E20: MAXEN TECHNOLOGIES SL | F20: Tier 2 | G20: 45966 | H20: Didac | I20: Pendiente | L20: Pendiente lead | N20: Pendiente lead
B21: 11 | C21: Lead 19 | E21: MAXEN TECHNOLOGIES SL | F21: Tier 2 | G21: 45966 | H21: Didac | I21: Pendiente | L21: Pendiente lead | N21: Pendiente lead
B22: 12 | C22: Magnetron | D22: A28325785 | E22: OX-ONE NETWORKS SL | F22: Tier 1 | G22: 46374 | H22: Jonathan Macías | I22: KO | L22: N/A | M22: N/A | N22: Alta complejidad técnica | O22: N/A
B23: 13 | C23: RUT PERFIL | E23: MAXEN TECHNOLOGIES SL | F23: Tier 2 | G23: 46009 | H23: Didac | I23: KO | L23: Seguimiento | M23: 46069 | N23: Nueva oferta con centralita enviada a cliente 20.02. Pendiente re-contacto con cliente | O23: 46081
B24: 14 | C24: Grupo Calillo | D24: B85380186 | E24: COVERNET | F24: Tier 2 | G24: 46376 | H24: Didac | I24: Venta realizada | J24: 46053 | K24: SoHo | L24: N/A | M24: 46065 | N24: N/A | O24: N/A | P24: 176.59 | Q24: 4 líneas móviles, 1 líneas FBB, 3 dispositivos, 3 terminales, Sin Centralita
B25: 15 | C25: AREXPRESS | D25: B86054921 | E25: COVERNET | F25: Tier 2 | G25: 46376 | H25: Didac | I25: Venta realizada | J25: 46053 | K25: SoHo | L25: N/A | M25: 46065 | N25: N/A | O25: N/A | P25: 243 | Q25: 5 líneas móviles, 1 líneas FBB, 3 dispositivos, 3 terminales, Con Centralita
B26: 16 | C26: RAIL 28 | D26: B87253795 | E26: COVERNET | F26: Tier 2 | G26: 46376 | H26: Didac | I26: Venta realizada | J26: TBD | K26: PYME | L26: Ampliación PYME. Nos pasa info para darle el OK semana que viene. | M26: 46105 | N26: Pendiente bloqueo operativo por proceso ampliaciones. | O26: TBD | P26: 304 | Q26: 9 líneas móviles, 1 línea FBB, Con Centralita
B27: 17 | C27: VPLATAS ASESORES FISCALES | D27: B83768366 | E27: COVERNET | F27: Tier 2 | G27: 46376 | H27: Didac | I27: En curso | K27: PYME | L27: Seguimiento dudas a resolver | M27: 46101 | N27: Pendiente respuesta dudas por Didac | O27: 46101
B28: 18 | C28: Florflex (vecino RUTPERFIL) | E28: MAXEN TECHNOLOGIES SL | F28: Tier 2 | G28: 46054 | H28: Didac | I28: KO | L28: Seguimiento | N28: Pendiente respuesta cliente (Rut). Ligado a la oferta RUTPERFIL | O28: 46069
B29: 19 | C29: KEIM ECOPAINT IBERICA SL | E29: MAXEN TECHNOLOGIES SL | F29: Tier 2 | G29: 46062 | H29: Didac | I29: Pendiente | L29: Seguimiento | N29: Pendiente re-contacto con cliente semana 23.02 | O29: 46081
B30: 20 | C30: Asociación Apromar | D30: G78295748 | E36115814 (Cliente +O) | E30: Dataqu | F30: Tier 1 | G30: 46035 | H30: Jonathan Macías | I30: En curso | L30: Preparar webinar junto a Dataqu. Pendiente datos Maria Sebastián y oferta Carmen Sánchez para descuento especial para socios. | M30: 46097 | N30: =+L30 -> Preparar webinar junto a Dataqu. Pendiente datos Maria Sebastián y oferta Carmen Sánchez para descuento especial para socios. | O30: =+M30 -> 46097
B31: 21 | C31: Schreiber Foods | D31: B82690082 (Cliente hasta 12/2025) | E31: Dataqu | F31: Tier 1 | G31: 46035 | H31: Jonathan Macías | I31: Pendiente | L31: Sesión presencial en +O el 13.02 | M31: 46066 | N31: Sesión presencial en +O el 13.02 | O31: 46066
B32: 22 | C32: Armadora Pereira | D32: A36630028 | E32: Dataqu | F32: Tier 1 | G32: 46035 | H32: Jonathan Macías | I32: Pendiente | L32: Pendiente reactivación por reestructuración interna. | M32: 46070 | N32: Pendiente reorganización interna y ajuste de cuotas de pesca para activación de lead. | O32: 46136
B33: 23 | C33: Grupo Adarsa | D33: Múltiples CIFs [TBD] | E33: Dataqu | F33: Tier 1 | G33: 46035 | H33: Jonathan Macías | I33: En curso | L33: Seguimiento. Habla 18.03 con ellos para organizar sesión online | M33: 46099 | N33: Pendiente fecha por Dataqu para visita presencial (semana 16.03) | O33: 46097
B34: 24 | C34: Lead 1 | D34: B95601795 | E34: DuoIT | F34: Tier 1 | G34: 46058 | H34: Jonathan Macías | I34: KO | L34: Pendiente enviar oferta a Angel (Jonathan) | M34: 46073 | N34: Asegurar aplicación máximo descuento sobre oferta - Jonathan hace PT (15/20%). Miércoles Carmen Sanchez Arias debería pasar oferta a 24 meses (ahora la tiene Jonathan a 36) | O34: 46070
B35: 25 | C35: Lead 1 | E35: OX-ONE NETWORKS SL | F35: Tier 1 | G35: 46062 | H35: Jonathan Macías | I35: KO | L35: Mail con precio licencias google competitivas compartido con Gonzalo por Jonathan el 18.02. Pendiente respuesta | M35: 46071 | N35: Gestión con GGCC [ 27 licencias Business plus de Google (el cliente paga 25,3€ actualmente) + centralita cisco (ox-one hace mantenimiento). Acaba permanencia 01.03] - Pendiente feedback | O35: 46087
B36: 26 | C36: Conchi | E36: Cobitratel | F36: Tier 1 | G36: 46065 | H36: Nazaret | I36: KO | L36: Pendiente Nazaret | M36: 46071 | N36: Pendiente reagendar reunión (inicialmente esperada para viernes 27.02) | O36: 46084
B37: 27 | C37: Lead 2 | E37: OX-ONE NETWORKS SL | F37: Tier 1 | G37: 46023 | H37: Jonathan Macías | I37: Pendiente | L37: Pendiente recibir lead (despacho abogados) | M37: 46066 | N37: Pendiente recibir lead | O37: 46066
B38: 28 | C38: Lead 3 | E38: OX-ONE NETWORKS SL | F38: Tier 1 | G38: 46023 | H38: Jonathan Macías | I38: Pendiente | L38: Pendiente recibir lead | M38: 46066 | N38: Pendiente recibir lead | O38: 46066
B39: 29 | C39: Duino Inversiones SL | E39: OX-ONE NETWORKS SL | F39: Tier 1 | G39: 46070 | H39: Jonathan Macías | I39: En curso | L39: Seguimiento | M39: 46090 | N39: Jonathan le envía la oferta 18.02 - 11 líneas móviles + 2 fibras 1GB + backup. Visita comercial pendiente de agendar desde semana 23.02). Llamada lunes 09.03 | O39: 46090
B40: 30 | C40: Adrián | E40: Cobitratel | F40: Tier 1 | G40: 46072 | H40: Sergio Mena | I40: KO | L40: N/A | M40: N/A | N40: Cliente no interesado en oferta con descuento | O40: N/A
B41: 31 | C41: Wecolors | E41: MAXEN TECHNOLOGIES SL | F41: Tier 2 | G41: 46070 | H41: Didac | I41: Pendiente | L41: Seguimiento | N41: Pendiente reagendar visita comercial (inicialmente planeada para 24.02) | O41: 46083
B42: 32 | C42: Expansiva | E42: MAXEN TECHNOLOGIES SL | F42: Tier 2 | G42: 46076 | H42: Didac | I42: En curso | L42: Seguimiento. Preguntar a Fernando Cifo si podemos venderle M2M (SIM para alarmas) a una empresa de seguridad pyme. A razon del mail q le envió a Didac, va a ir él con el integrador y quiere saber si le podemos proporcionar eso | M42: 46104 | N42: Primera visita el 25.03 | O42: 46106
...

Sheet Integradores Captados
B2: Funnel integradores
B3: 4.1 Activado: en proceso de firma
B4: 4.2 Activado: Firmado
B5: 3.1 Interés confirmado: pendiente agendar KO
B6: 3.2 Interés confirmado: agendado KO | P6: =+P8/L8 -> 0.41025641
H7: Integradores captados | I7: Integradores activados | J7: Contratos firmados | L7: Oportunidades en pipeline | N7: Visitas comerciales realizadas | P7: Ofertas realizadas | R7: Ventas formalizadas
H8: =+COUNTA(H13:H207) -> 34 | I8: =+COUNTIF(I13:I306,"Realizado")+COUNTIF(I13:I306,"En curso") -> 23 | J8: =+COUNTIF(J13:J306,"Realizado") -> 6 | L8: =+SUM(L13:L1048576) -> 39 | N8: =+SUM(N13:N1048576) -> 17 | P8: =+SUM(P13:P1048576) -> 16 | R8: =+SUM(R13:R1048576) -> 6
J9: =+J8/I8 -> 0.26086957 | N9: =+N8/L8 -> 0.43589744 | P9: =+P8/N8 -> 0.94117647 | R9: =+R8/P8 -> 0.375
F11: Primer contacto (telefónico) | G11: Acepta Sesión Informativa 1:1 (online) | H11: Acepta sesión Kick Off (presencial) | I11: ACTIVADO | T11: Formaciones
B12: # | C12: Integrador | D12: Estado | E12: Siguiente paso | F12: Hito #1: Contacto establecido | G12: Hito #2: Lead con interés | H12: Hito #3: Integrador captado | I12: Hito #4: Integrador activado | J12: Hito #5: Contrato firmado | K12: Modelo de colaboración | L12: Clientes potenciales identificados | M12: Visitas / clientes (%) | N12: Visitas comerciales (#) | O12: Ofertas / visitas (%) | P12: Ofertas (#) | Q12: Ventas / ofertas (%) | R12: Ventas (#) | S12: Responsable | T12: Producto SoHo | U12: Producto PYME (fijo y móvil) | V12: Producto PYME convergente (BIG PYME) | W12: Producto PYME (conecta empresas y ciberseguridad) | X12: Soluciones digitales PYME | Y12: Portal DHO | Z12: SIGNA | AA12: Mundo B2B PYME | AB12: Formulario BOC | AC12: Web Penalizaciones | AD12: ATAC | AE12: ATENCO | AF12: DEO, Parrilla, BT | AG12: PANGEA y ÁGORA | AH12: Alega
B13: =+_xlfn.XLOOKUP($C13,'Leads Priorizados INT'!$B:$B,'Leads Priorizados INT'!$A:$A) -> 85 | C13: OX-ONE NETWORKS SL | D13: =+_xlfn.XLOOKUP($C13,'Leads Priorizados INT'!$B:$B,'Leads Priorizados INT'!$E:$E) -> 4.1 Activado: en proceso de firma | E13: VVDD descarta la oportunidad. Pendiente recibir nuevos leads | F13: =+IF(OR($D13=$B$3,$D13=$B$4,$D13=$B$5,$D13=$B$6),"Realizado","Sin comenzar") -> Realizado | G13: =+IF(OR($D13=$B$3,$D13=$B$4,$D13=$B$5,$D13=$B$6),"Realizado","Sin comenzar") -> Realizado | H13: =+IF($D13=$B$5,"Pendiente",IF($D13=$B$6,"Agendado",IF(OR($D13=$B$3,$D13=$B$4),"Realizado"))) -> Realizado | I13: =+IF(OR($D13=$B$5,$D13=$B$6),"Sin comenzar",IF(OR($D13=$B$3,$D13=$B$4),"Realizado")) -> Realizado | J13: =+IF(OR($D13=$B$5,$D13=$B$6),"Sin comenzar",IF($D13=$B$3,"En curso",IF($D13=$B$4,"Realizado"))) -> En curso | K13: Tier 1 | L13: 3 | M13: 1 | N13: 1 | O13: 0 | P13: =IFERROR( COUNTIFS(Leads!$E$11:$E$5015,$C13,Leads!$I$11:$I$5015,"En curso") + COUNTIFS(Leads!$E$11:$E$5015,$C13,Leads!$I$11:$I$5015,"Venta realizada"),0) -> 2 | Q13: - | R13: =IFERROR( COUNTIFS(Leads!$E$11:$E$5015,$C13,Leads!$I$11:$I$5015,"Venta realizada"),0) -> 0 | S13: =+C13 -> OX-ONE NETWORKS SL | T13: Sin comenzar | U13: Sin comenzar | V13: Sin comenzar | W13: Sin comenzar | X13: Sin comenzar | Y13: Sin comenzar | Z13: Sin comenzar | AA13: Sin comenzar | AB13: Sin comenzar | AC13: Sin comenzar | AD13: Sin comenzar | AE13: Sin comenzar | AF13: Sin comenzar | AG13: Sin comenzar | AH13: Sin comenzar
B14: =+_xlfn.XLOOKUP($C14,'Leads Priorizados INT'!$B:$B,'Leads Priorizados INT'!$A:$A) -> 108 | C14: MAXEN TECHNOLOGIES SL | D14: =+_xlfn.XLOOKUP($C14,'Leads Priorizados INT'!$B:$B,'Leads Priorizados INT'!$E:$E) -> 4.2 Activado: Firmado | E14: Reunión con Didac 15.01 para ver más leads | F14: =+IF(OR($D14=$B$3,$D14=$B$4,$D14=$B$5,$D14=$B$6),"Realizado","Sin comenzar") -> Realizado | G14: =+IF(OR($D14=$B$3,$D14=$B$4,$D14=$B$5,$D14=$B$6),"Realizado","Sin comenzar") -> Realizado | H14: =+IF($D14=$B$5,"Pendiente",IF($D14=$B$6,"Agendado",IF(OR($D14=$B$3,$D14=$B$4),"Realizado"))) -> Realizado | I14: =+IF(OR($D14=$B$5,$D14=$B$6),"Sin comenzar",IF(OR($D14=$B$3,$D14=$B$4),"Realizado")) -> Realizado | J14: =+IF(OR($D14=$B$5,$D14=$B$6),"Sin comenzar",IF($D14=$B$3,"En curso",IF($D14=$B$4,"Realizado"))) -> Realizado | K14: Tier 2 | L14: 19 | M14: 0.1 | N14: 11 | O14: 1 | P14: =IFERROR( COUNTIFS(Leads!$E$11:$E$5015,$C14,Leads!$I$11:$I$5015,"En curso") + COUNTIFS(Leads!$E$11:$E$5015,$C14,Leads!$I$11:$I$5015,"Venta realizada"),0) -> 4 | Q14: 0.5 | R14: =IFERROR( COUNTIFS(Leads!$E$11:$E$5015,$C14,Leads!$I$11:$I$5015,"Venta realizada"),0) -> 1 | S14: =+B55 -> MAXEN TECHNOLOGIES SL | T14: Sin comenzar | U14: Realizado | V14: Sin comenzar | W14: Sin comenzar | X14: Realizado | Y14: Realizado | Z14: Realizado | AA14: Sin comenzar | AB14: Realizado | AC14: Sin comenzar | AD14: Sin comenzar | AE14: Sin comenzar | AF14: Sin comenzar | AG14: Sin comenzar | AH14: Sin comenzar
B15: =+_xlfn.XLOOKUP($C15,'Leads Priorizados INT'!$B:$B,'Leads Priorizados INT'!$A:$A) -> 114 | C15: PAPER LABS DESIGN ESP SL | D15: =+_xlfn.XLOOKUP($C15,'Leads Priorizados INT'!$B:$B,'Leads Priorizados INT'!$E:$E) -> 4.2 Activado: Firmado | E15: Agendar KickOff. Siguen agobiados con su BaU | F15: =+IF(OR($D15=$B$3,$D15=$B$4,$D15=$B$5,$D15=$B$6),"Realizado","Sin comenzar") -> Realizado | G15: =+IF(OR($D15=$B$3,$D15=$B$4,$D15=$B$5,$D15=$B$6),"Realizado","Sin comenzar") -> Realizado | H15: =+IF($D15=$B$5,"Pendiente",IF($D15=$B$6,"Agendado",IF(OR($D15=$B$3,$D15=$B$4),"Realizado"))) -> Realizado | I15: =+IF(OR($D15=$B$5,$D15=$B$6),"Sin comenzar",IF(OR($D15=$B$3,$D15=$B$4),"Realizado")) -> Realizado | J15: =+IF(OR($D15=$B$5,$D15=$B$6),"Sin comenzar",IF($D15=$B$3,"En curso",IF($D15=$B$4,"Realizado"))) -> Realizado | K15: TBC | L15: 0 | M15: - | N15: 0 | O15: - | P15: =IFERROR( COUNTIFS(Leads!$E$11:$E$5015,$C15,Leads!$I$11:$I$5015,"En curso") + COUNTIFS(Leads!$E$11:$E$5015,$C15,Leads!$I$11:$I$5015,"Venta realizada"),0) -> 0 | Q15: - | R15: =IFERROR( COUNTIFS(Leads!$E$11:$E$5015,$C15,Leads!$I$11:$I$5015,"Venta realizada"),0) -> 0 | S15: =+B56 -> PAPER LABS DESIGN ESP SL | T15: Sin comenzar | U15: Sin comenzar | V15: Sin comenzar | W15: Sin comenzar | X15: Sin comenzar | Y15: Sin comenzar | Z15: Sin comenzar | AA15: Sin comenzar | AB15: Sin comenzar | AC15: Sin comenzar | AD15: Sin comenzar | AE15: Sin comenzar | AF15: Sin comenzar | AG15: Sin comenzar | AH15: Sin comenzar
B16: =+_xlfn.XLOOKUP($C16,'Leads Priorizados INT'!$B:$B,'Leads Priorizados INT'!$A:$A) -> 147 | C16: DEITECO | D16: =+_xlfn.XLOOKUP($C16,'Leads Priorizados INT'!$B:$B,'Leads Priorizados INT'!$E:$E) -> 4.2 Activado: Firmado | E16: De momento, sin leads adicionales identificados | F16: =+IF(OR($D16=$B$3,$D16=$B$4,$D16=$B$5,$D16=$B$6),"Realizado","Sin comenzar") -> Realizado | G16: =+IF(OR($D16=$B$3,$D16=$B$4,$D16=$B$5,$D16=$B$6),"Realizado","Sin comenzar") -> Realizado | H16: =+IF($D16=$B$5,"Pendiente",IF($D16=$B$6,"Agendado",IF(OR($D16=$B$3,$D16=$B$4),"Realizado"))) -> Realizado | I16: =+IF(OR($D16=$B$5,$D16=$B$6),"Sin comenzar",IF(OR($D16=$B$3,$D16=$B$4),"Realizado")) -> Realizado | J16: =+IF(OR($D16=$B$5,$D16=$B$6),"Sin comenzar",IF($D16=$B$3,"En curso",IF($D16=$B$4,"Realizado"))) -> Realizado | K16: Tier 2 | L16: 0 | M16: 0 | N16: 0 | O16: - | P16: =IFERROR( COUNTIFS(Leads!$E$11:$E$5015,$C16,Leads!$I$11:$I$5015,"En curso") + COUNTIFS(Leads!$E$11:$E$5015,$C16,Leads!$I$11:$I$5015,"Venta realizada"),0) -> 0 | Q16: - | R16: =IFERROR( COUNTIFS(Leads!$E$11:$E$5015,$C16,Leads!$I$11:$I$5015,"Venta realizada"),0) -> 0 | S16: =+B57 -> DEITECO | T16: Sin comenzar | U16: Realizado | V16: Sin comenzar | W16: Sin comenzar | X16: Realizado | Y16: Realizado | Z16: Sin comenzar | AA16: Sin comenzar | AB16: Sin comenzar | AC16: Sin comenzar | AD16: Sin comenzar | AE16: Sin comenzar | AF16: Sin comenzar | AG16: Sin comenzar | AH16: Sin comenzar
B17: =+_xlfn.XLOOKUP($C17,'Leads Priorizados INT'!$B:$B,'Leads Priorizados INT'!$A:$A) -> 148 | C17: COVERNET | D17: =+_xlfn.XLOOKUP($C17,'Leads Priorizados INT'!$B:$B,'Leads Priorizados INT'!$E:$E) -> 4.2 Activado: Firmado | E17: 4 ofertas potenciales. Cover Net pide documentación a clientes para formalizar oferta y firmar. | F17: =+IF(OR($D17=$B$3,$D17=$B$4,$D17=$B$5,$D17=$B$6),"Realizado","Sin comenzar") -> Realizado | G17: =+IF(OR($D17=$B$3,$D17=$B$4,$D17=$B$5,$D17=$B$6),"Realizado","Sin comenzar") -> Realizado | H17: =+IF($D17=$B$5,"Pendiente",IF($D17=$B$6,"Agendado",IF(OR($D17=$B$3,$D17=$B$4),"Realizado"))) -> Realizado | I17: =+IF(OR($D17=$B$5,$D17=$B$6),"Sin comenzar",IF(OR($D17=$B$3,$D17=$B$4),"Realizado")) -> Realizado | J17: =+IF(OR($D17=$B$5,$D17=$B$6),"Sin comenzar",IF($D17=$B$3,"En curso",IF($D17=$B$4,"Realizado"))) -> Realizado | K17: Tier 2 | L17: 9 | M17: 1 | N17: 4 | O17: 1 | P17: =IFERROR( COUNTIFS(Leads!$E$11:$E$5015,$C17,Leads!$I$11:$I$5015,"En curso") + COUNTIFS(Leads!$E$11:$E$5015,$C17,Leads!$I$11:$I$5015,"Venta realizada"),0) -> 5 | Q17: 0 | R17: =IFERROR( COUNTIFS(Leads!$E$11:$E$5015,$C17,Leads!$I$11:$I$5015,"Venta realizada"),0) -> 4 | S17: =+B58 -> COVERNET | T17: Sin comenzar | U17: Realizado | V17: Sin comenzar | W17: Sin comenzar | X17: Realizado | Y17: Realizado | Z17: Realizado | AA17: Sin comenzar | AB17: Realizado | AC17: Sin comenzar | AD17: Sin comenzar | AE17: Sin comenzar | AF17: Sin comenzar | AG17: Sin comenzar | AH17: Sin comenzar
B18: =+_xlfn.XLOOKUP($C18,'Leads Priorizados INT'!$B:$B,'Leads Priorizados INT'!$A:$A) -> 654 | C18: SICTEMAS SERVICIOS INFORMATICOS INTEGRALES | D18: =+_xlfn.XLOOKUP($C18,'Leads Priorizados INT'!$B:$B,'Leads Priorizados INT'!$E:$E) -> 4.2 Activado: Firmado | E18: Recontacto 03.03 - Pendiente contrato firmado y leads | F18: =+IF(OR($D18=$B$3,$D18=$B$4,$D18=$B$5,$D18=$B$6),"Realizado","Sin comenzar") -> Realizado | G18: =+IF(OR($D18=$B$3,$D18=$B$4,$D18=$B$5,$D18=$B$6),"Realizado","Sin comenzar") -> Realizado | H18: =+IF($D18=$B$5,"Pendiente",IF($D18=$B$6,"Agendado",IF(OR($D18=$B$3,$D18=$B$4),"Realizado"))) -> Realizado | I18: =+IF(OR($D18=$B$5,$D18=$B$6),"Sin comenzar",IF(OR($D18=$B$3,$D18=$B$4),"Realizado")) -> Realizado | J18: =+IF(OR($D18=$B$5,$D18=$B$6),"Sin comenzar",IF($D18=$B$3,"En curso",IF($D18=$B$4,"Realizado"))) -> Realizado | K18: Tier 2 | L18: 0 | M18: - | N18: 0 | O18: - | P18: =IFERROR( COUNTIFS(Leads!$E$11:$E$5015,$C18,Leads!$I$11:$I$5015,"En curso") + COUNTIFS(Leads!$E$11:$E$5015,$C18,Leads!$I$11:$I$5015,"Venta realizada"),0) -> 0 | Q18: - | R18: =IFERROR( COUNTIFS(Leads!$E$11:$E$5015,$C18,Leads!$I$11:$I$5015,"Venta realizada"),0) -> 0 | S18: =+C18 -> SICTEMAS SERVICIOS INFORMATICOS INTEGRALES | T18: Sin comenzar | U18: Sin comenzar | V18: Sin comenzar | W18: Sin comenzar | X18: Sin comenzar | Y18: Sin comenzar | Z18: Sin comenzar | AA18: Sin comenzar | AB18: Sin comenzar | AC18: Sin comenzar | AD18: Sin comenzar | AE18: Sin comenzar | AF18: Sin comenzar | AG18: Sin comenzar | AH18: Sin comenzar
B19: =+_xlfn.XLOOKUP($C19,'Leads Priorizados INT'!$B:$B,'Leads Priorizados INT'!$A:$A) -> 668 | C19: Dataqu | D19: =+_xlfn.XLOOKUP($C19,'Leads Priorizados INT'!$B:$B,'Leads Priorizados INT'!$E:$E) -> 4.1 Activado: en proceso de firma | E19: Pendiente recibir ok final de Dataqu | F19: =+IF(OR($D19=$B$3,$D19=$B$4,$D19=$B$5,$D19=$B$6),"Realizado","Sin comenzar") -> Realizado | G19: =+IF(OR($D19=$B$3,$D19=$B$4,$D19=$B$5,$D19=$B$6),"Realizado","Sin comenzar") -> Realizado | H19: =+IF($D19=$B$5,"Pendiente",IF($D19=$B$6,"Agendado",IF(OR($D19=$B$3,$D19=$B$4),"Realizado"))) -> Realizado | I19: =+IF(OR($D19=$B$5,$D19=$B$6),"Sin comenzar",IF(OR($D19=$B$3,$D19=$B$4),"Realizado")) -> Realizado | J19: =+IF(OR($D19=$B$5,$D19=$B$6),"Sin comenzar",IF($D19=$B$3,"En curso",IF($D19=$B$4,"Realizado"))) -> En curso | K19: Tier 1 (antiguo LeadGen) | L19: 4 | M19: - | N19: 0 | O19: - | P19: =IFERROR( COUNTIFS(Leads!$E$11:$E$5015,$C19,Leads!$I$11:$I$5015,"En curso") + COUNTIFS(Leads!$E$11:$E$5015,$C19,Leads!$I$11:$I$5015,"Venta realizada"),0) -> 2 | Q19: - | R19: =IFERROR( COUNTIFS(Leads!$E$11:$E$5015,$C19,Leads!$I$11:$I$5015,"Venta realizada"),0) -> 0 | S19: =+C19 -> Dataqu | T19: Sin comenzar | U19: Sin comenzar | V19: Sin comenzar | W19: Sin comenzar | X19: Sin comenzar | Y19: Sin comenzar | Z19: Sin comenzar | AA19: Sin comenzar | AB19: Sin comenzar | AC19: Sin comenzar | AD19: Sin comenzar | AE19: Sin comenzar | AF19: Sin comenzar | AG19: Sin comenzar | AH19: Sin comenzar
B20: =+_xlfn.XLOOKUP($C20,'Leads Priorizados INT'!$B:$B,'Leads Priorizados INT'!$A:$A) -> 669 | C20: Ocvistas | D20: =+_xlfn.XLOOKUP($C20,'Leads Priorizados INT'!$B:$B,'Leads Priorizados INT'!$E:$E) -> 4.1 Activado: en proceso de firma | E20: Recontacto 02.03 - Pendiente contrato firmado y leads | F20: =+IF(OR($D20=$B$3,$D20=$B$4,$D20=$B$5,$D20=$B$6),"Realizado","Sin comenzar") -> Realizado | G20: =+IF(OR($D20=$B$3,$D20=$B$4,$D20=$B$5,$D20=$B$6),"Realizado","Sin comenzar") -> Realizado | H20: =+IF($D20=$B$5,"Pendiente",IF($D20=$B$6,"Agendado",IF(OR($D20=$B$3,$D20=$B$4),"Realizado"))) -> Realizado | I20: =+IF(OR($D20=$B$5,$D20=$B$6),"Sin comenzar",IF(OR($D20=$B$3,$D20=$B$4),"Realizado")) -> Realizado | J20: =+IF(OR($D20=$B$5,$D20=$B$6),"Sin comenzar",IF($D20=$B$3,"En curso",IF($D20=$B$4,"Realizado"))) -> En curso | K20: Tier 1 (antiguo LeadGen) | L20: 0 | M20: - | N20: 0 | O20: - | P20: =IFERROR( COUNTIFS(Leads!$E$11:$E$5015,$C20,Leads!$I$11:$I$5015,"En curso") + COUNTIFS(Leads!$E$11:$E$5015,$C20,Leads!$I$11:$I$5015,"Venta realizada"),0) -> 0 | Q20: - | R20: =IFERROR( COUNTIFS(Leads!$E$11:$E$5015,$C20,Leads!$I$11:$I$5015,"Venta realizada"),0) -> 0 | S20: Legal (+O) | T20: Sin comenzar | U20: Sin comenzar | V20: Sin comenzar | W20: Sin comenzar | X20: Sin comenzar | Y20: Sin comenzar | Z20: Sin comenzar | AA20: Sin comenzar | AB20: Sin comenzar | AC20: Sin comenzar | AD20: Sin comenzar | AE20: Sin comenzar | AF20: Sin comenzar | AG20: Sin comenzar | AH20: Sin comenzar
B21: =+_xlfn.XLOOKUP($C21,'Leads Priorizados INT'!$B:$B,'Leads Priorizados INT'!$A:$A) -> 670 | C21: DuoIT | D21: =+_xlfn.XLOOKUP($C21,'Leads Priorizados INT'!$B:$B,'Leads Priorizados INT'!$E:$E) -> 4.1 Activado: en proceso de firma | E21: Pendiente confirmación últimos cambios Tier 1 y leads a ofertar | F21: =+IF(OR($D21=$B$3,$D21=$B$4,$D21=$B$5,$D21=$B$6),"Realizado","Sin comenzar") -> Realizado | G21: =+IF(OR($D21=$B$3,$D21=$B$4,$D21=$B$5,$D21=$B$6),"Realizado","Sin comenzar") -> Realizado | H21: =+IF($D21=$B$5,"Pendiente",IF($D21=$B$6,"Agendado",IF(OR($D21=$B$3,$D21=$B$4),"Realizado"))) -> Realizado | I21: =+IF(OR($D21=$B$5,$D21=$B$6),"Sin comenzar",IF(OR($D21=$B$3,$D21=$B$4),"Realizado")) -> Realizado | J21: =+IF(OR($D21=$B$5,$D21=$B$6),"Sin comenzar",IF($D21=$B$3,"En curso",IF($D21=$B$4,"Realizado"))) -> En curso | K21: Tier 1 | L21: 1 | M21: 0 | N21: 0 | O21: - | P21: 1 | Q21: - | R21: =IFERROR( COUNTIFS(Leads!$E$11:$E$5015,$C21,Leads!$I$11:$I$5015,"Venta realizada"),0) -> 0 | S21: =+C21 -> DuoIT | T21: Sin comenzar | U21: Sin comenzar | V21: Sin comenzar | W21: Sin comenzar | X21: Sin comenzar | Y21: Sin comenzar | Z21: Sin comenzar | AA21: Sin comenzar | AB21: Sin comenzar | AC21: Sin comenzar | AD21: Sin comenzar | AE21: Sin comenzar | AF21: Sin comenzar | AG21: Sin comenzar | AH21: Sin comenzar
A22: x | B22: =+_xlfn.XLOOKUP($C22,'Leads Priorizados INT'!$B:$B,'Leads Priorizados INT'!$A:$A) -> 702 | C22: A4I | D22: =+_xlfn.XLOOKUP($C22,'Leads Priorizados INT'!$B:$B,'Leads Priorizados INT'!$E:$E) -> 3.3 Interés confirmado: on hold | E22: Pendiente agendar KickOff (sesión 1:1 online 9.01) | F22: =+IF(OR($D22=$B$3,$D22=$B$4,$D22=$B$5,$D22=$B$6),"Realizado","Sin comenzar") -> Sin comenzar | G22: =+IF(OR($D22=$B$3,$D22=$B$4,$D22=$B$5,$D22=$B$6),"Realizado","Sin comenzar") -> Sin comenzar | H22: =+IF($D22=$B$5,"Pendiente",IF($D22=$B$6,"Agendado",IF(OR($D22=$B$3,$D22=$B$4),"Realizado"))) -> FALSE | I22: =+IF(OR($D22=$B$5,$D22=$B$6),"Sin comenzar",IF(OR($D22=$B$3,$D22=$B$4),"Realizado")) -> FALSE | J22: =+IF(OR($D22=$B$5,$D22=$B$6),"Sin comenzar",IF($D22=$B$3,"En curso",IF($D22=$B$4,"Realizado"))) -> FALSE | K22: Sin comenzar | L22: Sin comenzar | M22: Sin comenzar | N22: Sin comenzar | O22: Sin comenzar | P22: Sin comenzar | Q22: Sin comenzar | R22: Sin comenzar | S22: =+B64 -> INFORNET SOLUCIONES INFORMATICAS S.L | T22: Sin comenzar | U22: Sin comenzar | V22: Sin comenzar | W22: Sin comenzar | X22: Sin comenzar | Y22: Sin comenzar | Z22: Sin comenzar | AA22: Sin comenzar | AB22: Sin comenzar | AC22: Sin comenzar | AD22: Sin comenzar | AE22: Sin comenzar | AF22: Sin comenzar | AG22: Sin comenzar | AH22: Sin comenzar
B23: =+_xlfn.XLOOKUP($C23,'Leads Priorizados INT'!$B:$B,'Leads Priorizados INT'!$A:$A) -> 736 | C23: FEDESOFT SL | D23: =+_xlfn.XLOOKUP($C23,'Leads Priorizados INT'!$B:$B,'Leads Priorizados INT'!$E:$E) -> 4.1 Activado: en proceso de firma | E23: Pendiente recibir info para firmar contrato y leads | F23: =+IF(OR($D23=$B$3,$D23=$B$4,$D23=$B$5,$D23=$B$6),"Realizado","Sin comenzar") -> Realizado | G23: =+IF(OR($D23=$B$3,$D23=$B$4,$D23=$B$5,$D23=$B$6),"Realizado","Sin comenzar") -> Realizado | H23: =+IF($D23=$B$5,"Pendiente",IF($D23=$B$6,"Agendado",IF(OR($D23=$B$3,$D23=$B$4),"Realizado"))) -> Realizado | I23: =+IF(OR($D23=$B$5,$D23=$B$6),"Sin comenzar",IF(OR($D23=$B$3,$D23=$B$4),"Realizado")) -> Realizado | J23: =+IF(OR($D23=$B$5,$D23=$B$6),"Sin comenzar",IF($D23=$B$3,"En curso",IF($D23=$B$4,"Realizado"))) -> En curso | K23: Tier 1 | L23: 0 | M23: - | N23: 0 | O23: - | P23: =IFERROR( COUNTIFS(Leads!$E$11:$E$5015,$C23,Leads!$I$11:$I$5015,"En curso") + COUNTIFS(Leads!$E$11:$E$5015,$C23,Leads!$I$11:$I$5015,"Venta realizada"),0) -> 0 | Q23: - | R23: =IFERROR( COUNTIFS(Leads!$E$11:$E$5015,$C23,Leads!$I$11:$I$5015,"Venta realizada"),0) -> 0 | S23: =+C23 -> FEDESOFT SL | T23: Sin comenzar | U23: Sin comenzar | V23: Sin comenzar | W23: Sin comenzar | X23: Sin comenzar | Y23: Sin comenzar | Z23: Sin comenzar | AA23: Sin comenzar | AB23: Sin comenzar | AC23: Sin comenzar | AD23: Sin comenzar | AE23: Sin comenzar | AF23: Sin comenzar | AG23: Sin comenzar | AH23: Sin comenzar
B24: =+_xlfn.XLOOKUP($C24,'Leads Priorizados INT'!$B:$B,'Leads Priorizados INT'!$A:$A) -> 757 | C24: INFORNET SOLUCIONES INFORMATICAS S.L | D24: =+_xlfn.XLOOKUP($C24,'Leads Priorizados INT'!$B:$B,'Leads Priorizados INT'!$E:$E) -> 4.1 Activado: en proceso de firma | E24: Pendiente recibir info para firmar contrato y leads | F24: =+IF(OR($D24=$B$3,$D24=$B$4,$D24=$B$5,$D24=$B$6),"Realizado","Sin comenzar") -> Realizado | G24: =+IF(OR($D24=$B$3,$D24=$B$4,$D24=$B$5,$D24=$B$6),"Realizado","Sin comenzar") -> Realizado | H24: =+IF($D24=$B$5,"Pendiente",IF($D24=$B$6,"Agendado",IF(OR($D24=$B$3,$D24=$B$4),"Realizado"))) -> Realizado | I24: =+IF(OR($D24=$B$5,$D24=$B$6),"Sin comenzar",IF(OR($D24=$B$3,$D24=$B$4),"Realizado")) -> Realizado | J24: =+IF(OR($D24=$B$5,$D24=$B$6),"Sin comenzar",IF($D24=$B$3,"En curso",IF($D24=$B$4,"Realizado"))) -> En curso | K24: Tier 1 | L24: 0 | M24: - | N24: 0 | O24: - | P24: =IFERROR( COUNTIFS(Leads!$E$11:$E$5015,$C24,Leads!$I$11:$I$5015,"En curso") + COUNTIFS(Leads!$E$11:$E$5015,$C24,Leads!$I$11:$I$5015,"Venta realizada"),0) -> 0 | Q24: - | R24: =IFERROR( COUNTIFS(Leads!$E$11:$E$5015,$C24,Leads!$I$11:$I$5015,"Venta realizada"),0) -> 0 | S24: =+C24 -> INFORNET SOLUCIONES INFORMATICAS S.L | T24: Sin comenzar | U24: Sin comenzar | V24: Sin comenzar | W24: Sin comenzar | X24: Sin comenzar | Y24: Sin comenzar | Z24: Sin comenzar | AA24: Sin comenzar | AB24: Sin comenzar | AC24: Sin comenzar | AD24: Sin comenzar | AE24: Sin comenzar | AF24: Sin comenzar | AG24: Sin comenzar | AH24: Sin comenzar
B25: =+_xlfn.XLOOKUP($C25,'Leads Priorizados INT'!$B:$B,'Leads Priorizados INT'!$A:$A) -> 919 | C25: Micro Sip | D25: =+_xlfn.XLOOKUP($C25,'Leads Priorizados INT'!$B:$B,'Leads Priorizados INT'!$E:$E) -> 4.1 Activado: en proceso de firma | E25: Pendiente KO | F25: =+IF(OR($D25=$B$3,$D25=$B$4,$D25=$B$5,$D25=$B$6),"Realizado","Sin comenzar") -> Realizado | G25: =+IF(OR($D25=$B$3,$D25=$B$4,$D25=$B$5,$D25=$B$6),"Realizado","Sin comenzar") -> Realizado | H25: =+IF($D25=$B$5,"Pendiente",IF($D25=$B$6,"Agendado",IF(OR($D25=$B$3,$D25=$B$4),"Realizado"))) -> Realizado | I25: =+IF(OR($D25=$B$5,$D25=$B$6),"Sin comenzar",IF(OR($D25=$B$3,$D25=$B$4),"Realizado")) -> Realizado | J25: =+IF(OR($D25=$B$5,$D25=$B$6),"Sin comenzar",IF($D25=$B$3,"En curso",IF($D25=$B$4,"Realizado"))) -> En curso | K25: TBC | L25: Sin comenzar | M25: Sin comenzar | N25: Sin comenzar | O25: Sin comenzar | P25: Sin comenzar | Q25: Sin comenzar | R25: Sin comenzar | S25: =+B68 -> Cobitratel | T25: Sin comenzar | U25: Sin comenzar | V25: Sin comenzar | W25: Sin comenzar | X25: Sin comenzar | Y25: Sin comenzar | Z25: Sin comenzar | AA25: Sin comenzar | AB25: Sin comenzar | AC25: Sin comenzar | AD25: Sin comenzar | AE25: Sin comenzar | AF25: Sin comenzar | AG25: Sin comenzar | AH25: Sin comenzar
B26: =+_xlfn.XLOOKUP($C26,'Leads Priorizados INT'!$B:$B,'Leads Priorizados INT'!$A:$A) -> 1381 | C26: LOOMIS SPAIN DIGITAL SERVICES SL. | D26: =+_xlfn.XLOOKUP($C26,'Leads Priorizados INT'!$B:$B,'Leads Priorizados INT'!$E:$E) -> 98. Churn | E26: No alineado con estrategia acutal | F26: =+IF(OR($D26=$B$3,$D26=$B$4,$D26=$B$5,$D26=$B$6),"Realizado","Sin comenzar") -> Sin comenzar | G26: =+IF(OR($D26=$B$3,$D26=$B$4,$D26=$B$5,$D26=$B$6),"Realizado","Sin comenzar") -> Sin comenzar | H26: =+IF($D26=$B$5,"Pendiente",IF($D26=$B$6,"Agendado",IF(OR($D26=$B$3,$D26=$B$4),"Realizado"))) -> FALSE | I26: =+IF(OR($D26=$B$5,$D26=$B$6),"Sin comenzar",IF(OR($D26=$B$3,$D26=$B$4),"Realizado")) -> FALSE | J26: =+IF(OR($D26=$B$5,$D26=$B$6),"Sin comenzar",IF($D26=$B$3,"En curso",IF($D26=$B$4,"Realizado"))) -> FALSE | K26: Tier 1 | L26: 0 | M26: - | N26: 0 | O26: - | P26: =IFERROR( COUNTIFS(Leads!$E$11:$E$5015,$C26,Leads!$I$11:$I$5015,"En curso") + COUNTIFS(Leads!$E$11:$E$5015,$C26,Leads!$I$11:$I$5015,"Venta realizada"),0) -> 0 | Q26: - | R26: =IFERROR( COUNTIFS(Leads!$E$11:$E$5015,$C26,Leads!$I$11:$I$5015,"Venta realizada"),0) -> 0 | S26: =+C26 -> LOOMIS SPAIN DIGITAL SERVICES SL. | T26: Sin comenzar | U26: Sin comenzar | V26: Sin comenzar | W26: Sin comenzar | X26: Sin comenzar | Y26: Sin comenzar | Z26: Sin comenzar | AA26: Sin comenzar | AB26: Sin comenzar | AC26: Sin comenzar | AD26: Sin comenzar | AE26: Sin comenzar | AF26: Sin comenzar | AG26: Sin comenzar | AH26: Sin comenzar
B27: =+_xlfn.XLOOKUP($C27,'Leads Priorizados INT'!$B:$B,'Leads Priorizados INT'!$A:$A) -> 1431 | C27: Cobitratel | D27: =+_xlfn.XLOOKUP($C27,'Leads Priorizados INT'!$B:$B,'Leads Priorizados INT'!$E:$E) -> 4.1 Activado: en proceso de firma | E27: Pendiente confirmación últimos cambios Tier 1 y leads a ofertar | F27: =+IF(OR($D27=$B$3,$D27=$B$4,$D27=$B$5,$D27=$B$6),"Realizado","Sin comenzar") -> Realizado | G27: =+IF(OR($D27=$B$3,$D27=$B$4,$D27=$B$5,$D27=$B$6),"Realizado","Sin comenzar") -> Realizado | H27: =+IF($D27=$B$5,"Pendiente",IF($D27=$B$6,"Agendado",IF(OR($D27=$B$3,$D27=$B$4),"Realizado"))) -> Realizado | I27: =+IF(OR($D27=$B$5,$D27=$B$6),"Sin comenzar",IF(OR($D27=$B$3,$D27=$B$4),"Realizado")) -> Realizado | J27: =+IF(OR($D27=$B$5,$D27=$B$6),"Sin comenzar",IF($D27=$B$3,"En curso",IF($D27=$B$4,"Realizado"))) -> En curso | K27: Tier 1 | L27: 2 | M27: Churn | N27: 1 | O27: Churn | P27: 2 | Q27: Churn | R27: =IFERROR( COUNTIFS(Leads!$E$11:$E$5015,$C27,Leads!$I$11:$I$5015,"Venta realizada"),0) -> 1 | S27: =+C27 -> Cobitratel | T27: Sin comenzar | U27: Sin comenzar | V27: Sin comenzar | W27: Sin comenzar | X27: Sin comenzar | Y27: Sin comenzar | Z27: Sin comenzar | AA27: Sin comenzar | AB27: Sin comenzar | AC27: Sin comenzar | AD27: Sin comenzar | AE27: Sin comenzar | AF27: Sin comenzar | AG27: Sin comenzar | AH27: Sin comenzar
A28: x | B28: =+_xlfn.XLOOKUP($C28,'Leads Priorizados INT'!$B:$B,'Leads Priorizados INT'!$A:$A) -> 541 | C28: NEXT MOBILITY SOLUTIONS SL | D28: =+_xlfn.XLOOKUP($C28,'Leads Priorizados INT'!$B:$B,'Leads Priorizados INT'!$E:$E) -> 3.3 Interés confirmado: on hold | E28: Pendiente respuesta para agendar KO (enviado mail 8.01) | F28: =+IF(OR($D28=$B$3,$D28=$B$4,$D28=$B$5,$D28=$B$6),"Realizado","Sin comenzar") -> Sin comenzar | G28: =+IF(OR($D28=$B$3,$D28=$B$4,$D28=$B$5,$D28=$B$6),"Realizado","Sin comenzar") -> Sin comenzar | H28: =+IF($D28=$B$5,"Pendiente",IF($D28=$B$6,"Agendado",IF(OR($D28=$B$3,$D28=$B$4),"Realizado"))) -> FALSE | I28: =+IF(OR($D28=$B$5,$D28=$B$6),"Sin comenzar",IF(OR($D28=$B$3,$D28=$B$4),"Realizado")) -> FALSE | J28: =+IF(OR($D28=$B$5,$D28=$B$6),"Sin comenzar",IF($D28=$B$3,"En curso",IF($D28=$B$4,"Realizado"))) -> FALSE | K28: TBC | L28: Sin comenzar | M28: Sin comenzar | N28: Sin comenzar | O28: Sin comenzar | P28: Sin comenzar | Q28: Sin comenzar | R28: Sin comenzar | S28: =+C28 -> NEXT MOBILITY SOLUTIONS SL | T28: Sin comenzar | U28: Sin comenzar | V28: Sin comenzar | W28: Sin comenzar | X28: Sin comenzar | Y28: Sin comenzar | Z28: Sin comenzar | AA28: Sin comenzar | AB28: Sin comenzar | AC28: Sin comenzar | AD28: Sin comenzar | AE28: Sin comenzar | AF28: Sin comenzar | AG28: Sin comenzar | AH28: Sin comenzar
B29: =+_xlfn.XLOOKUP($C29,'Leads Priorizados INT'!$B:$B,'Leads Priorizados INT'!$A:$A) -> 1090 | C29: TWISTIC DIGITAL, SOCIEDAD LIMITADA. | D29: =+_xlfn.XLOOKUP($C29,'Leads Priorizados INT'!$B:$B,'Leads Priorizados INT'!$E:$E) -> 98. Churn | E29: No ven oportunidad de colaboración | F29: =+IF(OR($D29=$B$3,$D29=$B$4,$D29=$B$5,$D29=$B$6),"Realizado","Sin comenzar") -> Sin comenzar | G29: =+IF(OR($D29=$B$3,$D29=$B$4,$D29=$B$5,$D29=$B$6),"Realizado","Sin comenzar") -> Sin comenzar | H29: =+IF($D29=$B$5,"Pendiente",IF($D29=$B$6,"Agendado",IF(OR($D29=$B$3,$D29=$B$4),"Realizado"))) -> FALSE | I29: =+IF(OR($D29=$B$5,$D29=$B$6),"Sin comenzar",IF(OR($D29=$B$3,$D29=$B$4),"Realizado")) -> FALSE | J29: =+IF(OR($D29=$B$5,$D29=$B$6),"Sin comenzar",IF($D29=$B$3,"En curso",IF($D29=$B$4,"Realizado"))) -> FALSE | K29: TBC | L29: Sin comenzar | M29: Sin comenzar | N29: Sin comenzar | O29: Sin comenzar | P29: Sin comenzar | Q29: Sin comenzar | R29: Sin comenzar | S29: =+C29 -> TWISTIC DIGITAL, SOCIEDAD LIMITADA. | T29: Sin comenzar | U29: Sin comenzar | V29: Sin comenzar | W29: Sin comenzar | X29: Sin comenzar | Y29: Sin comenzar | Z29: Sin comenzar | AA29: Sin comenzar | AB29: Sin comenzar | AC29: Sin comenzar | AD29: Sin comenzar | AE29: Sin comenzar | AF29: Sin comenzar | AG29: Sin comenzar | AH29: Sin comenzar
B30: =+_xlfn.XLOOKUP($C30,'Leads Priorizados INT'!$B:$B,'Leads Priorizados INT'!$A:$A) -> 1514 | C30: TECNOLOGIA ESTRATEGICA | D30: =+_xlfn.XLOOKUP($C30,'Leads Priorizados INT'!$B:$B,'Leads Priorizados INT'!$E:$E) -> 98. Churn | E30: Recontacto 03.03 - Sin respuesta | F30: =+IF(OR($D30=$B$3,$D30=$B$4,$D30=$B$5,$D30=$B$6),"Realizado","Sin comenzar") -> Sin comenzar | G30: =+IF(OR($D30=$B$3,$D30=$B$4,$D30=$B$5,$D30=$B$6),"Realizado","Sin comenzar") -> Sin comenzar | H30: =+IF($D30=$B$5,"Pendiente",IF($D30=$B$6,"Agendado",IF(OR($D30=$B$3,$D30=$B$4),"Realizado"))) -> FALSE | I30: =+IF(OR($D30=$B$5,$D30=$B$6),"Sin comenzar",IF(OR($D30=$B$3,$D30=$B$4),"Realizado")) -> FALSE | J30: =+IF(OR($D30=$B$5,$D30=$B$6),"Sin comenzar",IF($D30=$B$3,"En curso",IF($D30=$B$4,"Realizado"))) -> FALSE | K30: TBC | L30: Sin comenzar | N30: Sin comenzar | P30: Sin comenzar | Q30: Sin comenzar | R30: Sin comenzar | S30: =+C30 -> TECNOLOGIA ESTRATEGICA | T30: Sin comenzar | U30: Sin comenzar | V30: Sin comenzar | W30: Sin comenzar | X30: Sin comenzar | Y30: Sin comenzar | Z30: Sin comenzar | AA30: Sin comenzar | AB30: Sin comenzar | AC30: Sin comenzar | AD30: Sin comenzar | AE30: Sin comenzar | AF30: Sin comenzar | AG30: Sin comenzar | AH30: Sin comenzar
B31: =+_xlfn.XLOOKUP($C31,'Leads Priorizados INT'!$B:$B,'Leads Priorizados INT'!$A:$A) -> 1405 | C31: SISYTEC NETWORKS SL. | D31: =+_xlfn.XLOOKUP($C31,'Leads Priorizados INT'!$B:$B,'Leads Priorizados INT'!$E:$E) -> 4.1 Activado: en proceso de firma | E31: Recontacto 03.03 - Pendiente contrato firmado y leads. Nos ha mandado 1 frio | F31: =+IF(OR($D31=$B$3,$D31=$B$4,$D31=$B$5,$D31=$B$6),"Realizado","Sin comenzar") -> Realizado | G31: =+IF(OR($D31=$B$3,$D31=$B$4,$D31=$B$5,$D31=$B$6),"Realizado","Sin comenzar") -> Realizado | H31: =+IF($D31=$B$5,"Pendiente",IF($D31=$B$6,"Agendado",IF(OR($D31=$B$3,$D31=$B$4),"Realizado"))) -> Realizado | I31: =+IF(OR($D31=$B$5,$D31=$B$6),"Sin comenzar",IF(OR($D31=$B$3,$D31=$B$4),"Realizado")) -> Realizado | J31: =+IF(OR($D31=$B$5,$D31=$B$6),"Sin comenzar",IF($D31=$B$3,"En curso",IF($D31=$B$4,"Realizado"))) -> En curso | K31: TBC | L31: 1 | N31: Sin comenzar | P31: Sin comenzar | Q31: Sin comenzar | R31: Sin comenzar | S31: =+C31 -> SISYTEC NETWORKS SL. | T31: Sin comenzar | U31: Sin comenzar | V31: Sin comenzar | W31: Sin comenzar | X31: Sin comenzar | Y31: Sin comenzar | Z31: Sin comenzar | AA31: Sin comenzar | AB31: Sin comenzar | AC31: Sin comenzar | AD31: Sin comenzar | AE31: Sin comenzar | AF31: Sin comenzar | AG31: Sin comenzar | AH31: Sin comenzar
B32: =+_xlfn.XLOOKUP($C32,'Leads Priorizados INT'!$B:$B,'Leads Priorizados INT'!$A:$A) -> 974 | C32: AUDINFOR SYSTEM SL. | D32: =+_xlfn.XLOOKUP($C32,'Leads Priorizados INT'!$B:$B,'Leads Priorizados INT'!$E:$E) -> 4.1 Activado: en proceso de firma | E32: Pendiente contrato firmado y leads | F32: =+IF(OR($D32=$B$3,$D32=$B$4,$D32=$B$5,$D32=$B$6),"Realizado","Sin comenzar") -> Realizado | G32: =+IF(OR($D32=$B$3,$D32=$B$4,$D32=$B$5,$D32=$B$6),"Realizado","Sin comenzar") -> Realizado | H32: =+IF($D32=$B$5,"Pendiente",IF($D32=$B$6,"Agendado",IF(OR($D32=$B$3,$D32=$B$4),"Realizado"))) -> Realizado | I32: =+IF(OR($D32=$B$5,$D32=$B$6),"Sin comenzar",IF(OR($D32=$B$3,$D32=$B$4),"Realizado")) -> Realizado | J32: =+IF(OR($D32=$B$5,$D32=$B$6),"Sin comenzar",IF($D32=$B$3,"En curso",IF($D32=$B$4,"Realizado"))) -> En curso | K32: TBC | L32: Sin comenzar | N32: Sin comenzar | P32: Sin comenzar | Q32: Sin comenzar | R32: Sin comenzar | S32: =+C32 -> AUDINFOR SYSTEM SL. | T32: Sin comenzar | U32: Sin comenzar | V32: Sin comenzar | W32: Sin comenzar | X32: Sin comenzar | Y32: Sin comenzar | Z32: Sin comenzar | AA32: Sin comenzar | AB32: Sin comenzar | AC32: Sin comenzar | AD32: Sin comenzar | AE32: Sin comenzar | AF32: Sin comenzar | AG32: Sin comenzar | AH32: Sin comenzar
